<?xml version="1.0"?>
<robot name = "jaco">

    <material name="JacoGrey">
        <color rgba="0.2 0.2 0.9 1.0"/>
    </material>

      
      <!-- The base joint & link -->

      <link name="jaco_base_link">
        <visual>
        <material name="JacoGrey" />
          <!--origin xyz="0 0 -0.0525" rpy="0 0 0"/-->
          <origin xyz="0 0 0.0" rpy="0 0 0"/>
          <geometry>
            <mesh filename="package://jaco_description/meshes/joint_1.dae" 
                scale="0.001 0.001 0.001"/>
          </geometry>
        </visual>
      </link>


     <!-- First revolute joint & link -->

     <joint name="jaco_joint_1" type="revolute">
        <!--origin xyz="0 0 0.2102" rpy="0 0 0"/--> 
        <origin xyz="0 0 0.2725" rpy="0 0 0"/> 
        <axis xyz="0 0 -1" rpy="0 0 0"/>
        <parent link="jaco_base_link"/>
        <child link="jaco_link_1"/>
        <limit lower="-3.1415926535897931" upper="3.1415926535897931" effort="1" velocity="3.1415926535897931"/>
      </joint>
      <link name="jaco_link_1">
        <visual>
        <material name="JacoGrey" />
          <origin xyz="0 0 -0.12" rpy="0 0 -1.570796327"/>          
          <geometry>
            <mesh filename="package://jaco_description/meshes/joint_2.dae" 
                scale="0.001 0.001 0.001"/>
          </geometry>
        </visual>
      </link>

   <!-- Second revolute joint & link -->

     <joint name="jaco_joint_2" type="revolute">
        <origin xyz="0 0 0" rpy="-1.570796327 0 0"/>
        <axis xyz="0 0 1"/>
        <parent link="jaco_link_1"/>
        <child link="jaco_link_2"/>
        <limit lower="-3.6651914291881" upper="0.57595865315813" effort="1" velocity="3.1415926535897931"/>
      </joint>
      <link name="jaco_link_2">
        <visual>
        <material name="JacoGrey" />
          <origin xyz="0 0 0.015" rpy="0 1.570796327 0"/>
          <geometry>
            <mesh filename="package://jaco_description/meshes/joint_3.dae" 
                scale="0.001 0.001 0.001"/>
          </geometry>
        </visual>
      </link>
  
 <!-- Third revolute joint & link -->

    <joint name="jaco_joint_3" type="revolute">
        <origin xyz="0.4100 0 0.012" rpy="0 0 0"/>
        <axis xyz="0 0 -1"/>
        <parent link="jaco_link_2"/>
        <child link="jaco_link_3"/>
        <limit lower="-1.221730476396" upper="4.2935099599061" effort="1" velocity="3.1415926535897931"/>
      </joint>
      <link name="jaco_link_3">
        <visual>
        <material name="JacoGrey" />
          <origin xyz="0 0 -0.012" rpy="0 1.570796327 1.570796327"/>
          <geometry>
            <mesh filename="package://jaco_description/meshes/joint_4.dae" 
                scale="1.000 1.000 1.000"/>
          </geometry>
        </visual>
      </link>

    <!-- Fourth revolute joint & link -->
     <joint name="jaco_joint_4" type="revolute">
        <origin xyz="0 0.24927682300748782 0 " rpy="-1.570796327 0 0"/>
        <axis xyz="0 0 -1"/>
        <parent link="jaco_link_3"/>
        <child link="jaco_link_4"/>
        <limit lower="-3.1415926535897931" upper="3.1415926535897931" effort="1" velocity="3.1415926535897931"/>
      </joint>
      <link name="jaco_link_4">
        <visual>
        <material name="JacoGrey" />
          <origin xyz="0 0 -0.042276823" rpy="0 0 -1.570796327"/>
          <geometry>
            <mesh filename="package://jaco_description/meshes/joint_5.dae" 
                scale="0.001 0.001 0.001"/>
          </geometry>
        </visual>
      </link>

  <!-- Fifth revolute joint & link -->
     <joint name="jaco_joint_5" type="revolute">
        <origin xyz="0 -0.069262292 0.048497979" rpy="0.959931089 0 0"/>
        <axis xyz="0 0 -1"/>
        <parent link="jaco_link_4"/>
        <child link="jaco_link_5"/>
        <limit lower="-3.1415926535897931" upper="3.1415926535897931" effort="1" velocity="3.1415926535897931"/>
      </joint>
      <link name="jaco_link_5">
        <visual>
        <material name="JacoGrey" />
          <origin xyz="0 0 -0.042276823" rpy="0 -0.959931089 1.570796327"/>
          <geometry>
            <mesh filename="package://jaco_description/meshes/joint_6.dae" 
                scale="0.001 0.001 0.001"/>
          </geometry>
        </visual>
      </link>

  <!-- Sixth revolute joint & link -->
   	<joint name="jaco_joint_6" type="revolute">
        <!--origin xyz="0 -0.186174274 0.13036063" rpy="0.959931089 0 0"/-->
        <origin xyz="0 -0.186174274 0.13036063" rpy="-0.959931089 0 3.1415926535897931"/>
        <origin xyz="0 0 0" rpy="0 0 -3.14"/>
        <axis xyz="0 0 -1"/>
        <parent link="jaco_link_5"/>
        <child link="jaco_link_6"/>
        <limit lower="-3.5415926535897931" upper="3.5415926535897931" effort="1" velocity="3.1415926535897931"/>
      </joint>
      <link name="jaco_link_6">
        <visual>
          <material name="JacoGrey" />
          <!--origin xyz="0 0 -0.1850" rpy="0 0 -3.1415926535897931"/-->
          <origin xyz="0 0 -0.1850" rpy="0 0 0.0"/>                  
          <geometry>
            <mesh filename="package://jaco_description/meshes/hand_no_finger.stl" 
                scale="1 1 1"/>
          </geometry>
        </visual>
      </link>

<!-- First finger -->
   	<joint name="jaco_finger_joint_1" type="revolute">
        <origin xyz="0.036 -0.021 -0.07" rpy="0 0 0"/>
        <axis xyz="0 -1 0"/>
        <parent link="jaco_link_6"/>
        <child link="jaco_finger_link_1"/>
        <limit lower="-3.1415926535897931" upper="3.1415926535897931" effort="1" velocity="3.1415926535897931"/>
      </joint>
      <link name="jaco_finger_link_1">
        <visual>
        <material name="JacoGrey" />
          <origin xyz="0 0 0" rpy="0 0 3.1415926535897931"/>
          <geometry>
            <mesh filename="package://jaco_description/meshes/finger.dae" 
                scale="1 1 1"/>
          </geometry>
        </visual>
      </link>

  <!-- Second finger -->

   	<joint name="jaco_finger_joint_2" type="revolute">
        <origin xyz="-0.036 -0 -0.07" rpy="0 0 0"/>
        <axis xyz="0 1 0"/>
        <parent link="jaco_link_6"/>
        <child link="jaco_finger_link_2"/>
        <limit lower="-3.1415926535897931" upper="3.1415926535897931" effort="1" velocity="3.1415926535897931"/>
      </joint>
      <link name="jaco_finger_link_2">
        <visual>
        <material name="JacoGrey" />
          <origin xyz="0 0 0" rpy="0 0 0"/>
          <geometry>
            <mesh filename="package://jaco_description/meshes/finger.dae" 
                scale="1 1 1"/>
          </geometry>
        </visual>
      </link>  


      
 <!-- Third finger -->
   	<joint name="jaco_finger_joint_3" type="revolute">
        <origin xyz="0.036 0.021 -0.07" rpy="0 0 0"/>
        <axis xyz="0 -1 0"/>
        <parent link="jaco_link_6"/>
        <child link="jaco_finger_link_3"/>
        <limit lower="-3.1415926535897931" upper="3.1415926535897931" effort="1" velocity="3.1415926535897931"/>
      </joint>
      <link name="jaco_finger_link_3">
        <visual>
        <material name="JacoGrey" />
          <origin xyz="0 0 0" rpy="0 0 3.1415926535897931"/>
              <geometry>
            <mesh filename="package://jaco_description/meshes/finger.dae" 
                scale="1 1 1"/>
          </geometry>
        </visual>
      </link>
      
 
</robot>

